Workbook

Sheet Cover
B2: GAJIAN AMAN — Business Model & Cost Financial Model
B3: Cost Structure • Revenue Model • Pricing Tiers • Scenario Analysis • P&L
B5: Version | C5: v2.0 — May 2026
B6: Currency | C6: IDR primary | USD reference | Rate: 16,000 IDR/USD (editable in Assumptions)
B7: Model type | C7: Bottom-up activity-based cost model + subscription revenue model
B8: User range | C8: 10 → 10,000 registered users
B9: Scenarios | C9: Conservative (0.6x) / Base (1.0x) / Growth (1.5x) activity multiplier
B12: SHEET INDEX
B13: 1. Assumptions | C13: All input variables: pricing, behavior, FX, infra thresholds, plan features
B14: 2. Pricing Plans | C14: Free / Starter / Pro / Business plan definition — features, limits, prices
B15: 3. AI Cost | C15: Claude Haiku API token consumption & cost (USD + IDR) per user count
B16: 4. Infra Cost | C16: Railway, Supabase, Vercel tier costs (USD + IDR) by user threshold
B17: 5. Revenue Model | C17: User mix by plan × price → MRR, ARR, ARPU, growth projection
B18: 6. P&L Summary | C18: Revenue minus cost = gross profit, margin, breakeven analysis
B19: 7. Scenario | C19: Conservative / Base / Growth P&L comparison across 100 / 500 / 1,000 users
B22: COLOR LEGEND
B23: Blue on Yellow = Editable input — change these
B24: Green = Cross-sheet formula link
B25: Blue background = Subtotal / Total row
B26: Teal background = Revenue / profit row

Sheet Assumptions
B1: ASSUMPTIONS — All Editable Inputs
B2: Blue = input you can change | Black = formula | Green = cross-sheet link
B4: A. USER BEHAVIOR — TELEGRAM BOT
B5: Daily Active Users (% of total) | C5: 0.4 | D5: % | E5: 40% of users send msg on any given day
B6: Text transactions per DAU per day | C6: 7 | D6: tx/day | E6: Natural language messages to bot
B7: Image transactions per DAU per day | C7: 1 | D7: img/day | E7: Receipt / e-wallet screenshot
B8: Active days per month | C8: 30 | D8: days
B10: B. USER BEHAVIOR — WEB DASHBOARD
B11: Web Monthly Active Users (% of total) | C11: 75 | D11: % | E11: 60% use dashboard at least once/mo
B12: Web sessions per MAU per month | C12: 8 | D12: sessions/mo
B13: Image uploads per web session | C13: 3 | D13: img/session
B15: C. CLAUDE HAIKU API PRICING
B16: ⚠ Claude Pro license ($20/mo) is for claude.ai personal use — API is billed separately per token
B17: Haiku input price (USD per 1M tokens) | C17: 0.8 | D17: USD/1M | E17: claude-haiku-4-5 current rate
B18: Haiku output price (USD per 1M tokens) | C18: 4 | D18: USD/1M | E18: claude-haiku-4-5 current rate
B20: D. TOKEN ESTIMATES PER CALL
B21: Text categorize — input tokens | C21: 350 | D21: tokens | E21: System prompt 250 + user message 100
B22: Text categorize — output tokens | C22: 80 | D22: tokens | E22: JSON: category, type, confidence
B23: Image parse bot — input tokens | C23: 1800 | D23: tokens | E23: ~1,500 image + 300 system prompt
B24: Image parse bot — output tokens | C24: 150 | D24: tokens | E24: Parsed JSON response
B25: Image parse web — input tokens | C25: 2000 | D25: tokens | E25: Slightly larger context via Vercel API
B26: Image parse web — output tokens | C26: 180 | D26: tokens | E26: Full structured JSON
B27: NLP full text mode — input tokens | C27: 500 | D27: tokens | E27: Free-chat parsing scenario
B28: NLP full text mode — output tokens | C28: 150 | D28: tokens | E28: Extraction + confirmation
B30: E. FIXED INFRASTRUCTURE COSTS (USD/mo)
B31: Railway (bot + scheduler) | C31: 5 | D31: USD/mo | E31: Current paid plan
B32: Supabase Free tier | C32: 0 | D32: USD/mo | E32: 500MB DB, 2GB transfer
B33: Vercel Free tier | C33: 0 | D33: USD/mo | E33: 100GB bandwidth, serverless
B34: Claude Pro personal license | C34: 20 | D34: USD/mo | E34: claude.ai access — NOT API cost
B36: F. INFRASTRUCTURE SCALE THRESHOLDS
B37: Supabase → Pro threshold (users) | C37: 100 | D37: users
B38: Supabase Pro cost | C38: 25 | D38: USD/mo
B39: Vercel → Pro threshold (users) | C39: 500 | D39: users
B40: Vercel Pro cost | C40: 20 | D40: USD/mo
B41: Railway → Scale threshold (users) | C41: 200 | D41: users
B42: Railway Scale cost | C42: 10 | D42: USD/mo
B43: Supabase → Team threshold (users) | C43: 1000 | D43: users
B44: Supabase Team cost | C44: 599 | D44: USD/mo
B46: G. EXCHANGE RATE
B47: IDR per 1 USD | C47: 17350 | D47: IDR/USD | E47: Update as needed
...

Sheet Pricing Plans
B1: PRICING PLANS — Gajian Aman Subscription Tiers
B2: Define price (IDR/mo) and features per tier. Prices feed Revenue Model.
C4: FREE | D4: STARTER | E4: PRO | F4: BUSINESS
B5: Monthly Price (IDR) | C5: 0 | D5: 9999 | E5: 24999 | F5: 34999
B6: Annual Price Equivalent (IDR) | C6: =C5*12 -> 0 | D6: =D5*12 -> 119988 | E6: =E5*12 -> 299988 | F6: =F5*12 -> 419988
B7: Monthly Price (USD equiv.) | C7: =C5/Assumptions!C47 -> 0 | D7: =D5/Assumptions!C47 -> 0.57631124 | E7: =E5/Assumptions!C47 -> 1.4408646 | F7: =F5/Assumptions!C47 -> 2.0172334
B10: Telegram bot — text command (/add, /income) | C10: ✓ | D10: ✓ | E10: ✓ | F10: ✓
B11: Telegram bot — natural language free chat | C11: ✗ | D11: ✓ | E11: ✓ | F11: ✓
B12: Receipt image upload (bot) | C12: 3/mo | D12: 20/mo | E12: Unlimited | F12: Unlimited
B13: Receipt image upload (web) | C13: ✗ | D13: 10/mo | E13: Unlimited | F13: Unlimited
B14: Backdated entry (@DD/MM syntax) | C14: ✓ | D14: ✓ | E14: ✓ | F14: ✓
B15: Bulk import (CSV) | C15: ✗ | D15: ✗ | E15: ✓ | F15: ✓
B17: AI auto-categorization (text) | C17: ✓ | D17: ✓ | E17: ✓ | F17: ✓
B18: AI image parsing (receipt OCR) | C18: 3/mo | D18: 20/mo | E18: Unlimited | F18: Unlimited
B19: AI spending insights & tips | C19: ✗ | D19: ✗ | E19: ✓ | F19: ✓
B20: AI budget recommendations | C20: ✗ | D20: ✗ | E20: ✓ | F20: ✓
B21: Custom AI category training | C21: ✗ | D21: ✗ | E21: ✗ | F21: ✓
B23: Web dashboard access | C23: ✗ | D23: ✓ | E23: ✓ | F23: ✓
... B42: Shared budget dashboard | C42: ✗ | D42: ✗ | E42: ✗ | F42: ✓

Sheet AI Cost
B1: AI COST — Claude Haiku API Consumption
B2: USD and IDR for every cost row. Change inputs in Assumptions sheet.
B4: Metric | C4: 10 users | D4: 50 users | E4: 100 users | F4: 200 users | G4: 500 users | H4: 1,000 users | I4: 2,000 users | J4: 5,000 users | K4: 10,000 users | L4: Unit
B5: A. MONTHLY ACTIVITY VOLUME
B6: Daily Active Users (bot) | C6: =ROUND(10*Assumptions!C5,0) -> 4 | D6: =ROUND(50*Assumptions!C5,0) -> 20 | E6: =ROUND(100*Assumptions!C5,0) -> 40 | F6: =ROUND(200*Assumptions!C5,0) -> 80 | G6: =ROUND(500*Assumptions!C5,0) -> 200 | H6: =ROUND(1000*Assumptions!C5,0) -> 400 | I6: =ROUND(2000*Assumptions!C5,0) -> 800 | J6: =ROUND(5000*Assumptions!C5,0) -> 2000 | K6: =ROUND(10000*Assumptions!C5,0) -> 4000 | L6: users/day
B7: Text transactions / month | C7: =ROUND(10*Assumptions!C5*Assumptions!C6*Assumptions!C8,0) -> 840 | D7: =ROUND(50*Assumptions!C5*Assumptions!C6*Assumptions!C8,0) -> 4200 | E7: =ROUND(100*Assumptions!C5*Assumptions!C6*Assumptions!C8,0) -> 8400 | F7: =ROUND(200*Assumptions!C5*Assumptions!C6*Assumptions!C8,0) -> 16800 | G7: =ROUND(500*Assumptions!C5*Assumptions!C6*Assumptions!C8,0) -> 42000 | H7: =ROUND(1000*Assumptions!C5*Assumptions!C6*Assumptions!C8,0) -> 84000 | I7: =ROUND(2000*Assumptions!C5*Assumptions!C6*Assumptions!C8,0) -> 168000 | J7: =ROUND(5000*Assumptions!C5*Assumptions!C6*Assumptions!C8,0) -> 420000 | K7: =ROUND(10000*Assumptions!C5*Assumptions!C6*Assumptions!C8,0) -> 840000 | L7: tx/mo
B8: Image tx / month (bot) | C8: =ROUND(10*Assumptions!C5*Assumptions!C7*Assumptions!C8,0) -> 120 | D8: =ROUND(50*Assumptions!C5*Assumptions!C7*Assumptions!C8,0) -> 600 | E8: =ROUND(100*Assumptions!C5*Assumptions!C7*Assumptions!C8,0) -> 1200 | F8: =ROUND(200*Assumptions!C5*Assumptions!C7*Assumptions!C8,0) -> 2400 | G8: =ROUND(500*Assumptions!C5*Assumptions!C7*Assumptions!C8,0) -> 6000 | H8: =ROUND(1000*Assumptions!C5*Assumptions!C7*Assumptions!C8,0) -> 12000 | I8: =ROUND(2000*Assumptions!C5*Assumptions!C7*Assumptions!C8,0) -> 24000 | J8: =ROUND(5000*Assumptions!C5*Assumptions!C7*Assumptions!C8,0) -> 60000 | K8: =ROUND(10000*Assumptions!C5*Assumptions!C7*Assumptions!C8,0) -> 120000 | L8: img/mo
B9: Web MAU | C9: =ROUND(10*Assumptions!C11,0) -> 750 | D9: =ROUND(50*Assumptions!C11,0) -> 3750 | E9: =ROUND(100*Assumptions!C11,0) -> 7500 | F9: =ROUND(200*Assumptions!C11,0) -> 15000 | G9: =ROUND(500*Assumptions!C11,0) -> 37500 | H9: =ROUND(1000*Assumptions!C11,0) -> 75000 | I9: =ROUND(2000*Assumptions!C11,0) -> 150000 | J9: =ROUND(5000*Assumptions!C11,0) -> 375000 | K9: =ROUND(10000*Assumptions!C11,0) -> 750000 | L9: users/mo
B10: Image uploads / month (web) | C10: =ROUND(10*Assumptions!C11*Assumptions!C12*Assumptions!C13,0) -> 18000 | D10: =ROUND(50*Assumptions!C11*Assumptions!C12*Assumptions!C13,0) -> 90000 | E10: =ROUND(100*Assumptions!C11*Assumptions!C12*Assumptions!C13,0) -> 180000 | F10: =ROUND(200*Assumptions!C11*Assumptions!C12*Assumptions!C13,0) -> 360000 | G10: =ROUND(500*Assumptions!C11*Assumptions!C12*Assumptions!C13,0) -> 900000 | H10: =ROUND(1000*Assumptions!C11*Assumptions!C12*Assumptions!C13,0) -> 1800000 | I10: =ROUND(2000*Assumptions!C11*Assumptions!C12*Assumptions!C13,0) -> 3600000 | J10: =ROUND(5000*Assumptions!C11*Assumptions!C12*Assumptions!C13,0) -> 9000000 | K10: =ROUND(10000*Assumptions!C11*Assumptions!C12*Assumptions!C13,0) -> 18000000 | L10: img/mo
B12: B. TOKEN CONSUMPTION / MONTH
B13: Text categ. — input tokens | C13: =ROUND(10*Assumptions!C5*Assumptions!C6*Assumptions!C8*Assumptions!C21,0) -> 294000 | D13: =ROUND(50*Assumptions!C5*Assumptions!C6*Assumptions!C8*Assumptions!C21,0) -> 1470000 | E13: =ROUND(100*Assumptions!C5*Assumptions!C6*Assumptions!C8*Assumptions!C21,0) -> 2940000 | F13: =ROUND(200*Assumptions!C5*Assumptions!C6*Assumptions!C8*Assumptions!C21,0) -> 5880000 | G13: =ROUND(500*Assumptions!C5*Assumptions!C6*Assumptions!C8*Assumptions!C21,0) -> 14700000 | H13: =ROUND(1000*Assumptions!C5*Assumptions!C6*Assumptions!C8*Assumptions!C21,0) -> 29400000 | I13: =ROUND(2000*Assumptions!C5*Assumptions!C6*Assumptions!C8*Assumptions!C21,0) -> 58800000 | J13: =ROUND(5000*Assumptions!C5*Assumptions!C6*Assumptions!C8*Assumptions!C21,0) -> 147000000 | K13: =ROUND(10000*Assumptions!C5*Assumptions!C6*Assumptions!C8*Assumptions!C21,0) -> 294000000 | L13: tokens/mo
B14: Text categ. — output tokens | C14: =ROUND(10*Assumptions!C5*Assumptions!C6*Assumptions!C8*Assumptions!C22,0) -> 67200 | D14: =ROUND(50*Assumptions!C5*Assumptions!C6*Assumptions!C8*Assumptions!C22,0) -> 336000 | E14: =ROUND(100*Assumptions!C5*Assumptions!C6*Assumptions!C8*Assumptions!C22,0) -> 672000 | F14: =ROUND(200*Assumptions!C5*Assumptions!C6*Assumptions!C8*Assumptions!C22,0) -> 1344000 | G14: =ROUND(500*Assumptions!C5*Assumptions!C6*Assumptions!C8*Assumptions!C22,0) -> 3360000 | H14: =ROUND(1000*Assumptions!C5*Assumptions!C6*Assumptions!C8*Assumptions!C22,0) -> 6720000 | I14: =ROUND(2000*Assumptions!C5*Assumptions!C6*Assumptions!C8*Assumptions!C22,0) -> 13440000 | J14: =ROUND(5000*Assumptions!C5*Assumptions!C6*Assumptions!C8*Assumptions!C22,0) -> 33600000 | K14: =ROUND(10000*Assumptions!C5*Assumptions!C6*Assumptions!C8*Assumptions!C22,0) -> 67200000 | L14: tokens/mo
B15: Image bot — input tokens | C15: =ROUND(10*Assumptions!C5*Assumptions!C7*Assumptions!C8*Assumptions!C23,0) -> 216000 | D15: =ROUND(50*Assumptions!C5*Assumptions!C7*Assumptions!C8*Assumptions!C23,0) -> 1080000 | E15: =ROUND(100*Assumptions!C5*Assumptions!C7*Assumptions!C8*Assumptions!C23,0) -> 2160000 | F15: =ROUND(200*Assumptions!C5*Assumptions!C7*Assumptions!C8*Assumptions!C23,0) -> 4320000 | G15: =ROUND(500*Assumptions!C5*Assumptions!C7*Assumptions!C8*Assumptions!C23,0) -> 10800000 | H15: =ROUND(1000*Assumptions!C5*Assumptions!C7*Assumptions!C8*Assumptions!C23,0) -> 21600000 | I15: =ROUND(2000*Assumptions!C5*Assumptions!C7*Assumptions!C8*Assumptions!C23,0) -> 43200000 | J15: =ROUND(5000*Assumptions!C5*Assumptions!C7*Assumptions!C8*Assumptions!C23,0) -> 108000000 | K15: =ROUND(10000*Assumptions!C5*Assumptions!C7*Assumptions!C8*Assumptions!C23,0) -> 216000000 | L15: tokens/mo
B16: Image bot — output tokens | C16: =ROUND(10*Assumptions!C5*Assumptions!C7*Assumptions!C8*Assumptions!C24,0) -> 18000 | D16: =ROUND(50*Assumptions!C5*Assumptions!C7*Assumptions!C8*Assumptions!C24,0) -> 90000 | E16: =ROUND(100*Assumptions!C5*Assumptions!C7*Assumptions!C8*Assumptions!C24,0) -> 180000 | F16: =ROUND(200*Assumptions!C5*Assumptions!C7*Assumptions!C8*Assumptions!C24,0) -> 360000 | G16: =ROUND(500*Assumptions!C5*Assumptions!C7*Assumptions!C8*Assumptions!C24,0) -> 900000 | H16: =ROUND(1000*Assumptions!C5*Assumptions!C7*Assumptions!C8*Assumptions!C24,0) -> 1800000 | I16: =ROUND(2000*Assumptions!C5*Assumptions!C7*Assumptions!C8*Assumptions!C24,0) -> 3600000 | J16: =ROUND(5000*Assumptions!C5*Assumptions!C7*Assumptions!C8*Assumptions!C24,0) -> 9000000 | K16: =ROUND(10000*Assumptions!C5*Assumptions!C7*Assumptions!C8*Assumptions!C24,0) -> 18000000 | L16: tokens/mo
B17: Image web — input tokens | C17: =ROUND(10*Assumptions!C11*Assumptions!C12*Assumptions!C13*Assumptions!C25,0) -> 36000000 | D17: =ROUND(50*Assumptions!C11*Assumptions!C12*Assumptions!C13*Assumptions!C25,0) -> 180000000 | E17: =ROUND(100*Assumptions!C11*Assumptions!C12*Assumptions!C13*Assumptions!C25,0) -> 360000000 | F17: =ROUND(200*Assumptions!C11*Assumptions!C12*Assumptions!C13*Assumptions!C25,0) -> 720000000 | G17: =ROUND(500*Assumptions!C11*Assumptions!C12*Assumptions!C13*Assumptions!C25,0) -> 1800000000 | H17: =ROUND(1000*Assumptions!C11*Assumptions!C12*Assumptions!C13*Assumptions!C25,0) -> 3600000000 | I17: =ROUND(2000*Assumptions!C11*Assumptions!C12*Assumptions!C13*Assumptions!C25,0) -> 7200000000 | J17: =ROUND(5000*Assumptions!C11*Assumptions!C12*Assumptions!C13*Assumptions!C25,0) -> 18000000000 | K17: =ROUND(10000*Assumptions!C11*Assumptions!C12*Assumptions!C13*Assumptions!C25,0) -> 36000000000 | L17: tokens/mo
B18: Image web — output tokens | C18: =ROUND(10*Assumptions!C11*Assumptions!C12*Assumptions!C13*Assumptions!C26,0) -> 3240000 | D18: =ROUND(50*Assumptions!C11*Assumptions!C12*Assumptions!C13*Assumptions!C26,0) -> 16200000 | E18: =ROUND(100*Assumptions!C11*Assumptions!C12*Assumptions!C13*Assumptions!C26,0) -> 32400000 | F18: =ROUND(200*Assumptions!C11*Assumptions!C12*Assumptions!C13*Assumptions!C26,0) -> 64800000 | G18: =ROUND(500*Assumptions!C11*Assumptions!C12*Assumptions!C13*Assumptions!C26,0) -> 162000000 | H18: =ROUND(1000*Assumptions!C11*Assumptions!C12*Assumptions!C13*Assumptions!C26,0) -> 324000000 | I18: =ROUND(2000*Assumptions!C11*Assumptions!C12*Assumptions!C13*Assumptions!C26,0) -> 648000000 | J18: =ROUND(5000*Assumptions!C11*Assumptions!C12*Assumptions!C13*Assumptions!C26,0) -> 1620000000 | K18: =ROUND(10000*Assumptions!C11*Assumptions!C12*Assumptions!C13*Assumptions!C26,0) -> 3240000000 | L18: tokens/mo
B19: TOTAL Input tokens | C19: =C13+C15+C17 -> 36510000 | D19: =D13+D15+D17 -> 182550000 | E19: =E13+E15+E17 -> 365100000 | F19: =F13+F15+F17 -> 730200000 | G19: =G13+G15+G17 -> 1825500000 | H19: =H13+H15+H17 -> 3651000000 | I19: =I13+I15+I17 -> 7302000000 | J19: =J13+J15+J17 -> 18255000000 | K19: =K13+K15+K17 -> 36510000000 | L19: tokens/mo
B20: TOTAL Output tokens | C20: =C14+C16+C18 -> 3325200 | D20: =D14+D16+D18 -> 16626000 | E20: =E14+E16+E18 -> 33252000 | F20: =F14+F16+F18 -> 66504000 | G20: =G14+G16+G18 -> 166260000 | H20: =H14+H16+H18 -> 332520000 | I20: =I14+I16+I18 -> 665040000 | J20: =J14+J16+J18 -> 1662600000 | K20: =K14+K16+K18 -> 3325200000 | L20: tokens/mo
B22: C. AI COST — USD
B23: Input token cost (USD) | C23: =C19/1000000*Assumptions!C17 -> 29.208 | D23: =D19/1000000*Assumptions!C17 -> 146.04 | E23: =E19/1000000*Assumptions!C17 -> 292.08 | F23: =F19/1000000*Assumptions!C17 -> 584.16 | G23: =G19/1000000*Assumptions!C17 -> 1460.4 | H23: =H19/1000000*Assumptions!C17 -> 2920.8 | I23: =I19/1000000*Assumptions!C17 -> 5841.6 | J23: =J19/1000000*Assumptions!C17 -> 14604 | K23: =K19/1000000*Assumptions!C17 -> 29208 | L23: USD/mo
B24: Output token cost (USD) | C24: =C20/1000000*Assumptions!C18 -> 13.3008 | D24: =D20/1000000*Assumptions!C18 -> 66.504 | E24: =E20/1000000*Assumptions!C18 -> 133.008 | F24: =F20/1000000*Assumptions!C18 -> 266.016 | G24: =G20/1000000*Assumptions!C18 -> 665.04 | H24: =H20/1000000*Assumptions!C18 -> 1330.08 | I24: =I20/1000000*Assumptions!C18 -> 2660.16 | J24: =J20/1000000*Assumptions!C18 -> 6650.4 | K24: =K20/1000000*Assumptions!C18 -> 13300.8 | L24: USD/mo
B25: TOTAL AI Cost (USD/mo) | C25: =C23+C24 -> 42.5088 | D25: =D23+D24 -> 212.544 | E25: =E23+E24 -> 425.088 | F25: =F23+F24 -> 850.176 | G25: =G23+G24 -> 2125.44 | H25: =H23+H24 -> 4250.88 | I25: =I23+I24 -> 8501.76 | J25: =J23+J24 -> 21254.4 | K25: =K23+K24 -> 42508.8 | L25: USD/mo
B26: AI Cost per User (USD/mo) | C26: =C25/10 -> 4.25088 | D26: =D25/50 -> 4.25088 | E26: =E25/100 -> 4.25088 | F26: =F25/200 -> 4.25088 | G26: =G25/500 -> 4.25088 | H26: =H25/1000 -> 4.25088 | I26: =I25/2000 -> 4.25088 | J26: =J25/5000 -> 4.25088 | K26: =K25/10000 -> 4.25088 | L26: USD/user
B28: D. AI COST — IDR
B29: TOTAL AI Cost (IDR/mo) | C29: =C25*Assumptions!C47 -> 737527.68 | D29: =D25*Assumptions!C47 -> 3687638.4 | E29: =E25*Assumptions!C47 -> 7375276.8 | F29: =F25*Assumptions!C47 -> 14750554 | G29: =G25*Assumptions!C47 -> 36876384 | H29: =H25*Assumptions!C47 -> 73752768 | I29: =I25*Assumptions!C47 -> 147505536 | J29: =J25*Assumptions!C47 -> 368763840 | K29: =K25*Assumptions!C47 -> 737527680 | L29: IDR/mo
B30: AI Cost per User (IDR/mo) | C30: =C26*Assumptions!C47 -> 73752.768 | D30: =D26*Assumptions!C47 -> 73752.768 | E30: =E26*Assumptions!C47 -> 73752.768 | F30: =F26*Assumptions!C47 -> 73752.768 | G30: =G26*Assumptions!C47 -> 73752.768 | H30: =H26*Assumptions!C47 -> 73752.768 | I30: =I26*Assumptions!C47 -> 73752.768 | J30: =J26*Assumptions!C47 -> 73752.768 | K30: =K26*Assumptions!C47 -> 73752.768 | L30: IDR/user
B32: E. NLP MODE — Full Natural Language Bot (scenario)
B33: Replaces command mode (/add → free chat). Tokens increase ~43% per text call.
B34: NLP input tokens / month | C34: =ROUND(10*Assumptions!C5*Assumptions!C6*Assumptions!C8*Assumptions!C27,0) -> 420000 | D34: =ROUND(50*Assumptions!C5*Assumptions!C6*Assumptions!C8*Assumptions!C27,0) -> 2100000 | E34: =ROUND(100*Assumptions!C5*Assumptions!C6*Assumptions!C8*Assumptions!C27,0) -> 4200000 | F34: =ROUND(200*Assumptions!C5*Assumptions!C6*Assumptions!C8*Assumptions!C27,0) -> 8400000 | G34: =ROUND(500*Assumptions!C5*Assumptions!C6*Assumptions!C8*Assumptions!C27,0) -> 21000000 | H34: =ROUND(1000*Assumptions!C5*Assumptions!C6*Assumptions!C8*Assumptions!C27,0) -> 42000000 | I34: =ROUND(2000*Assumptions!C5*Assumptions!C6*Assumptions!C8*Assumptions!C27,0) -> 84000000 | J34: =ROUND(5000*Assumptions!C5*Assumptions!C6*Assumptions!C8*Assumptions!C27,0) -> 210000000 | K34: =ROUND(10000*Assumptions!C5*Assumptions!C6*Assumptions!C8*Assumptions!C27,0) -> 420000000 | L34: tokens/mo
B35: NLP output tokens / month | C35: =ROUND(10*Assumptions!C5*Assumptions!C6*Assumptions!C8*Assumptions!C28,0) -> 126000 | D35: =ROUND(50*Assumptions!C5*Assumptions!C6*Assumptions!C8*Assumptions!C28,0) -> 630000 | E35: =ROUND(100*Assumptions!C5*Assumptions!C6*Assumptions!C8*Assumptions!C28,0) -> 1260000 | F35: =ROUND(200*Assumptions!C5*Assumptions!C6*Assumptions!C8*Assumptions!C28,0) -> 2520000 | G35: =ROUND(500*Assumptions!C5*Assumptions!C6*Assumptions!C8*Assumptions!C28,0) -> 6300000 | H35: =ROUND(1000*Assumptions!C5*Assumptions!C6*Assumptions!C8*Assumptions!C28,0) -> 12600000 | I35: =ROUND(2000*Assumptions!C5*Assumptions!C6*Assumptions!C8*Assumptions!C28,0) -> 25200000 | J35: =ROUND(5000*Assumptions!C5*Assumptions!C6*Assumptions!C8*Assumptions!C28,0) -> 63000000 | K35: =ROUND(10000*Assumptions!C5*Assumptions!C6*Assumptions!C8*Assumptions!C28,0) -> 126000000 | L35: tokens/mo
B36: TOTAL AI Cost NLP (USD/mo) | C36: =(C34+C15+C17)/1000000*Assumptions!C17+(C35+C16+C18)/1000000*Assumptions!C18 -> 42.8448 | D36: =(D34+D15+D17)/1000000*Assumptions!C17+(D35+D16+D18)/1000000*Assumptions!C18 -> 214.224 | E36: =(E34+E15+E17)/1000000*Assumptions!C17+(E35+E16+E18)/1000000*Assumptions!C18 -> 428.448 | F36: =(F34+F15+F17)/1000000*Assumptions!C17+(F35+F16+F18)/1000000*Assumptions!C18 -> 856.896 | G36: =(G34+G15+G17)/1000000*Assumptions!C17+(G35+G16+G18)/1000000*Assumptions!C18 -> 2142.24 | H36: =(H34+H15+H17)/1000000*Assumptions!C17+(H35+H16+H18)/1000000*Assumptions!C18 -> 4284.48 | I36: =(I34+I15+I17)/1000000*Assumptions!C17+(I35+I16+I18)/1000000*Assumptions!C18 -> 8568.96 | J36: =(J34+J15+J17)/1000000*Assumptions!C17+(J35+J16+J18)/1000000*Assumptions!C18 -> 21422.4 | K36: =(K34+K15+K17)/1000000*Assumptions!C17+(K35+K16+K18)/1000000*Assumptions!C18 -> 42844.8 | L36: USD/mo
B37: TOTAL AI Cost NLP (IDR/mo) | C37: =C36*Assumptions!C47 -> 743357.28 | D37: =D36*Assumptions!C47 -> 3716786.4 | E37: =E36*Assumptions!C47 -> 7433572.8 | F37: =F36*Assumptions!C47 -> 14867146 | G37: =G36*Assumptions!C47 -> 37167864 | H37: =H36*Assumptions!C47 -> 74335728 | I37: =I36*Assumptions!C47 -> 1.4867146e+08 | J37: =J36*Assumptions!C47 -> 371678640 | K37: =K36*Assumptions!C47 -> 743357280 | L37: IDR/mo
B38: Delta vs command mode (IDR/mo) | C38: =C37-C29 -> 5829.6 | D38: =D37-D29 -> 29148 | E38: =E37-E29 -> 58296 | F38: =F37-F29 -> 116592 | G38: =G37-G29 -> 291480 | H38: =H37-H29 -> 582960 | I38: =I37-I29 -> 1165920 | J38: =J37-J29 -> 2914800 | K38: =K37-K29 -> 5829600 | L38: IDR/mo

Sheet Infra Cost
B1: INFRASTRUCTURE COST — Tier-based Scaling
B2: Auto-switches tier at defined user thresholds. Both USD and IDR shown.
B4: Service | C4: 10 users | D4: 50 users | E4: 100 users | F4: 200 users | G4: 500 users | H4: 1,000 users | I4: 2,000 users | J4: 5,000 users | K4: 10,000 users | L4: Note
B5: USD COSTS
B6: Railway (bot + scheduler) USD | C6: =IF(10>=Assumptions!C41,Assumptions!C42,Assumptions!C31) -> 5 | D6: =IF(50>=Assumptions!C41,Assumptions!C42,Assumptions!C31) -> 5 | E6: =IF(100>=Assumptions!C41,Assumptions!C42,Assumptions!C31) -> 5 | F6: =IF(200>=Assumptions!C41,Assumptions!C42,Assumptions!C31) -> 10 | G6: =IF(500>=Assumptions!C41,Assumptions!C42,Assumptions!C31) -> 10 | H6: =IF(1000>=Assumptions!C41,Assumptions!C42,Assumptions!C31) -> 10 | I6: =IF(2000>=Assumptions!C41,Assumptions!C42,Assumptions!C31) -> 10 | J6: =IF(5000>=Assumptions!C41,Assumptions!C42,Assumptions!C31) -> 10 | K6: =IF(10000>=Assumptions!C41,Assumptions!C42,Assumptions!C31) -> 10 | L6: $5→$10 at 200+ users
B7: Supabase (database) USD | C7: =IF(10>=Assumptions!C43,Assumptions!C44,IF(10>=Assumptions!C37,Assumptions!C38,Assumptions!C32)) -> 0 | D7: =IF(50>=Assumptions!C43,Assumptions!C44,IF(50>=Assumptions!C37,Assumptions!C38,Assumptions!C32)) -> 0 | E7: =IF(100>=Assumptions!C43,Assumptions!C44,IF(100>=Assumptions!C37,Assumptions!C38,Assumptions!C32)) -> 25 | F7: =IF(200>=Assumptions!C43,Assumptions!C44,IF(200>=Assumptions!C37,Assumptions!C38,Assumptions!C32)) -> 25 | G7: =IF(500>=Assumptions!C43,Assumptions!C44,IF(500>=Assumptions!C37,Assumptions!C38,Assumptions!C32)) -> 25 | H7: =IF(1000>=Assumptions!C43,Assumptions!C44,IF(1000>=Assumptions!C37,Assumptions!C38,Assumptions!C32)) -> 599 | I7: =IF(2000>=Assumptions!C43,Assumptions!C44,IF(2000>=Assumptions!C37,Assumptions!C38,Assumptions!C32)) -> 599 | J7: =IF(5000>=Assumptions!C43,Assumptions!C44,IF(5000>=Assumptions!C37,Assumptions!C38,Assumptions!C32)) -> 599 | K7: =IF(10000>=Assumptions!C43,Assumptions!C44,IF(10000>=Assumptions!C37,Assumptions!C38,Assumptions!C32)) -> 599 | L7: Free→$25(Pro)→$599(Team)
B8: Vercel (frontend + serverless) USD | C8: =IF(10>=Assumptions!C39,Assumptions!C40,Assumptions!C33) -> 0 | D8: =IF(50>=Assumptions!C39,Assumptions!C40,Assumptions!C33) -> 0 | E8: =IF(100>=Assumptions!C39,Assumptions!C40,Assumptions!C33) -> 0 | F8: =IF(200>=Assumptions!C39,Assumptions!C40,Assumptions!C33) -> 0 | G8: =IF(500>=Assumptions!C39,Assumptions!C40,Assumptions!C33) -> 20 | H8: =IF(1000>=Assumptions!C39,Assumptions!C40,Assumptions!C33) -> 20 | I8: =IF(2000>=Assumptions!C39,Assumptions!C40,Assumptions!C33) -> 20 | J8: =IF(5000>=Assumptions!C39,Assumptions!C40,Assumptions!C33) -> 20 | K8: =IF(10000>=Assumptions!C39,Assumptions!C40,Assumptions!C33) -> 20 | L8: Free→$20 at 500+ users
B9: Claude Pro license USD | C9: =Assumptions!C34 -> 20 | D9: =Assumptions!C34 -> 20 | E9: =Assumptions!C34 -> 20 | F9: =Assumptions!C34 -> 20 | G9: =Assumptions!C34 -> 20 | H9: =Assumptions!C34 -> 20 | I9: =Assumptions!C34 -> 20 | J9: =Assumptions!C34 -> 20 | K9: =Assumptions!C34 -> 20 | L9: Fixed — personal license
B10: TOTAL Infrastructure (USD/mo) | C10: =C6+C7+C8+C9 -> 25 | D10: =D6+D7+D8+D9 -> 25 | E10: =E6+E7+E8+E9 -> 50 | F10: =F6+F7+F8+F9 -> 55 | G10: =G6+G7+G8+G9 -> 75 | H10: =H6+H7+H8+H9 -> 649 | I10: =I6+I7+I8+I9 -> 649 | J10: =J6+J7+J8+J9 -> 649 | K10: =K6+K7+K8+K9 -> 649 | L10: USD/mo
B12: IDR EQUIVALENT
B13: Railway IDR | C13: =C6*Assumptions!C47 -> 86750 | D13: =D6*Assumptions!C47 -> 86750 | E13: =E6*Assumptions!C47 -> 86750 | F13: =F6*Assumptions!C47 -> 173500 | G13: =G6*Assumptions!C47 -> 173500 | H13: =H6*Assumptions!C47 -> 173500 | I13: =I6*Assumptions!C47 -> 173500 | J13: =J6*Assumptions!C47 -> 173500 | K13: =K6*Assumptions!C47 -> 173500 | L13: IDR/mo
B14: Supabase IDR | C14: =C7*Assumptions!C47 -> 0 | D14: =D7*Assumptions!C47 -> 0 | E14: =E7*Assumptions!C47 -> 433750 | F14: =F7*Assumptions!C47 -> 433750 | G14: =G7*Assumptions!C47 -> 433750 | H14: =H7*Assumptions!C47 -> 10392650 | I14: =I7*Assumptions!C47 -> 10392650 | J14: =J7*Assumptions!C47 -> 10392650 | K14: =K7*Assumptions!C47 -> 10392650 | L14: IDR/mo
B15: Vercel IDR | C15: =C8*Assumptions!C47 -> 0 | D15: =D8*Assumptions!C47 -> 0 | E15: =E8*Assumptions!C47 -> 0 | F15: =F8*Assumptions!C47 -> 0 | G15: =G8*Assumptions!C47 -> 347000 | H15: =H8*Assumptions!C47 -> 347000 | I15: =I8*Assumptions!C47 -> 347000 | J15: =J8*Assumptions!C47 -> 347000 | K15: =K8*Assumptions!C47 -> 347000 | L15: IDR/mo
B16: Claude Pro IDR | C16: =C9*Assumptions!C47 -> 347000 | D16: =D9*Assumptions!C47 -> 347000 | E16: =E9*Assumptions!C47 -> 347000 | F16: =F9*Assumptions!C47 -> 347000 | G16: =G9*Assumptions!C47 -> 347000 | H16: =H9*Assumptions!C47 -> 347000 | I16: =I9*Assumptions!C47 -> 347000 | J16: =J9*Assumptions!C47 -> 347000 | K16: =K9*Assumptions!C47 -> 347000 | L16: IDR/mo
B17: TOTAL Infrastructure (IDR/mo) | C17: =C10*Assumptions!C47 -> 433750 | D17: =D10*Assumptions!C47 -> 433750 | E17: =E10*Assumptions!C47 -> 867500 | F17: =F10*Assumptions!C47 -> 954250 | G17: =G10*Assumptions!C47 -> 1301250 | H17: =H10*Assumptions!C47 -> 11260150 | I17: =I10*Assumptions!C47 -> 11260150 | J17: =J10*Assumptions!C47 -> 11260150 | K17: =K10*Assumptions!C47 -> 11260150 | L17: IDR/mo
B19: TIER REFERENCE
B20: Railway tier | C20: =IF(10>=Assumptions!C41,"Scale $10/mo","Hobby $5/mo") -> Hobby $5/mo | D20: =IF(50>=Assumptions!C41,"Scale $10/mo","Hobby $5/mo") -> Hobby $5/mo | E20: =IF(100>=Assumptions!C41,"Scale $10/mo","Hobby $5/mo") -> Hobby $5/mo | F20: =IF(200>=Assumptions!C41,"Scale $10/mo","Hobby $5/mo") -> Scale $10/mo | G20: =IF(500>=Assumptions!C41,"Scale $10/mo","Hobby $5/mo") -> Scale $10/mo | H20: =IF(1000>=Assumptions!C41,"Scale $10/mo","Hobby $5/mo") -> Scale $10/mo | I20: =IF(2000>=Assumptions!C41,"Scale $10/mo","Hobby $5/mo") -> Scale $10/mo | J20: =IF(5000>=Assumptions!C41,"Scale $10/mo","Hobby $5/mo") -> Scale $10/mo | K20: =IF(10000>=Assumptions!C41,"Scale $10/mo","Hobby $5/mo") -> Scale $10/mo
B21: Supabase tier | C21: =IF(10>=Assumptions!C43,"Team $599/mo",IF(10>=Assumptions!C37,"Pro $25/mo","Free")) -> Free | D21: =IF(50>=Assumptions!C43,"Team $599/mo",IF(50>=Assumptions!C37,"Pro $25/mo","Free")) -> Free | E21: =IF(100>=Assumptions!C43,"Team $599/mo",IF(100>=Assumptions!C37,"Pro $25/mo","Free")) -> Pro $25/mo | F21: =IF(200>=Assumptions!C43,"Team $599/mo",IF(200>=Assumptions!C37,"Pro $25/mo","Free")) -> Pro $25/mo | G21: =IF(500>=Assumptions!C43,"Team $599/mo",IF(500>=Assumptions!C37,"Pro $25/mo","Free")) -> Pro $25/mo | H21: =IF(1000>=Assumptions!C43,"Team $599/mo",IF(1000>=Assumptions!C37,"Pro $25/mo","Free")) -> Team $599/mo | I21: =IF(2000>=Assumptions!C43,"Team $599/mo",IF(2000>=Assumptions!C37,"Pro $25/mo","Free")) -> Team $599/mo | J21: =IF(5000>=Assumptions!C43,"Team $599/mo",IF(5000>=Assumptions!C37,"Pro $25/mo","Free")) -> Team $599/mo | K21: =IF(10000>=Assumptions!C43,"Team $599/mo",IF(10000>=Assumptions!C37,"Pro $25/mo","Free")) -> Team $599/mo
B22: Vercel tier | C22: =IF(10>=Assumptions!C39,"Pro $20/mo","Free") -> Free | D22: =IF(50>=Assumptions!C39,"Pro $20/mo","Free") -> Free | E22: =IF(100>=Assumptions!C39,"Pro $20/mo","Free") -> Free | F22: =IF(200>=Assumptions!C39,"Pro $20/mo","Free") -> Free | G22: =IF(500>=Assumptions!C39,"Pro $20/mo","Free") -> Pro $20/mo | H22: =IF(1000>=Assumptions!C39,"Pro $20/mo","Free") -> Pro $20/mo | I22: =IF(2000>=Assumptions!C39,"Pro $20/mo","Free") -> Pro $20/mo | J22: =IF(5000>=Assumptions!C39,"Pro $20/mo","Free") -> Pro $20/mo | K22: =IF(10000>=Assumptions!C39,"Pro $20/mo","Free") -> Pro $20/mo

Sheet Revenue Model
B1: REVENUE MODEL — Subscription MRR by User Count
B2: Plan mix % and prices from Pricing Plans sheet. Edit mix % in blue rows.
B4: Metric | C4: 10 users | D4: 50 users | E4: 100 users | F4: 200 users | G4: 500 users | H4: 1,000 users | I4: 2,000 users | J4: 5,000 users | K4: 10,000 users | L4: Unit
B5: A. USER MIX BY PLAN (editable — must sum to 100%)
B6: % Free users | C6: 0.6 | D6: 0.6 | E6: 0.6 | F6: 0.6 | G6: 0.6 | H6: 0.6 | I6: 0.6 | J6: 0.6 | K6: 0.6 | L6: %
B7: % Starter users | C7: 0.25 | D7: 0.25 | E7: 0.25 | F7: 0.25 | G7: 0.25 | H7: 0.25 | I7: 0.25 | J7: 0.25 | K7: 0.25 | L7: %
B8: % Pro users | C8: 0.12 | D8: 0.12 | E8: 0.12 | F8: 0.12 | G8: 0.12 | H8: 0.12 | I8: 0.12 | J8: 0.12 | K8: 0.12 | L8: %
B9: % Business users | C9: 0.03 | D9: 0.03 | E9: 0.03 | F9: 0.03 | G9: 0.03 | H9: 0.03 | I9: 0.03 | J9: 0.03 | K9: 0.03 | L9: %
B10: Sum (must = 100%) | C10: =C6+C7+C8+C9 -> 1 | D10: =D6+D7+D8+D9 -> 1 | E10: =E6+E7+E8+E9 -> 1 | F10: =F6+F7+F8+F9 -> 1 | G10: =G6+G7+G8+G9 -> 1 | H10: =H6+H7+H8+H9 -> 1 | I10: =I6+I7+I8+I9 -> 1 | J10: =J6+J7+J8+J9 -> 1 | K10: =K6+K7+K8+K9 -> 1
B12: B. USER COUNT BY PLAN
B13: Free users | C13: =ROUND(10*C6,0) -> 6 | D13: =ROUND(50*D6,0) -> 30 | E13: =ROUND(100*E6,0) -> 60 | F13: =ROUND(200*F6,0) -> 120 | G13: =ROUND(500*G6,0) -> 300 | H13: =ROUND(1000*H6,0) -> 600 | I13: =ROUND(2000*I6,0) -> 1200 | J13: =ROUND(5000*J6,0) -> 3000 | K13: =ROUND(10000*K6,0) -> 6000 | L13: users
B14: Starter users | C14: =ROUND(10*C7,0) -> 3 | D14: =ROUND(50*D7,0) -> 13 | E14: =ROUND(100*E7,0) -> 25 | F14: =ROUND(200*F7,0) -> 50 | G14: =ROUND(500*G7,0) -> 125 | H14: =ROUND(1000*H7,0) -> 250 | I14: =ROUND(2000*I7,0) -> 500 | J14: =ROUND(5000*J7,0) -> 1250 | K14: =ROUND(10000*K7,0) -> 2500 | L14: users
B15: Pro users | C15: =ROUND(10*C8,0) -> 1 | D15: =ROUND(50*D8,0) -> 6 | E15: =ROUND(100*E8,0) -> 12 | F15: =ROUND(200*F8,0) -> 24 | G15: =ROUND(500*G8,0) -> 60 | H15: =ROUND(1000*H8,0) -> 120 | I15: =ROUND(2000*I8,0) -> 240 | J15: =ROUND(5000*J8,0) -> 600 | K15: =ROUND(10000*K8,0) -> 1200 | L15: users
B16: Business users | C16: =ROUND(10*C9,0) -> 0 | D16: =ROUND(50*D9,0) -> 2 | E16: =ROUND(100*E9,0) -> 3 | F16: =ROUND(200*F9,0) -> 6 | G16: =ROUND(500*G9,0) -> 15 | H16: =ROUND(1000*H9,0) -> 30 | I16: =ROUND(2000*I9,0) -> 60 | J16: =ROUND(5000*J9,0) -> 150 | K16: =ROUND(10000*K9,0) -> 300 | L16: users
B17: TOTAL Paid users | C17: =C14+C15+C16 -> 4 | D17: =D14+D15+D16 -> 21 | E17: =E14+E15+E16 -> 40 | F17: =F14+F15+F16 -> 80 | G17: =G14+G15+G16 -> 200 | H17: =H14+H15+H16 -> 400 | I17: =I14+I15+I16 -> 800 | J17: =J14+J15+J16 -> 2000 | K17: =K14+K15+K16 -> 4000 | L17: users
B19: C. PLAN PRICES (from Pricing Plans sheet)
B20: Free price (IDR/mo) | C20: ='Pricing Plans'!C5 -> 0 | D20: ='Pricing Plans'!C5 -> 0 | E20: ='Pricing Plans'!C5 -> 0 | F20: ='Pricing Plans'!C5 -> 0 | G20: ='Pricing Plans'!C5 -> 0 | H20: ='Pricing Plans'!C5 -> 0 | I20: ='Pricing Plans'!C5 -> 0 | J20: ='Pricing Plans'!C5 -> 0 | K20: ='Pricing Plans'!C5 -> 0 | L20: IDR/mo
B21: Starter price (IDR/mo) | C21: ='Pricing Plans'!D5 -> 9999 | D21: ='Pricing Plans'!D5 -> 9999 | E21: ='Pricing Plans'!D5 -> 9999 | F21: ='Pricing Plans'!D5 -> 9999 | G21: ='Pricing Plans'!D5 -> 9999 | H21: ='Pricing Plans'!D5 -> 9999 | I21: ='Pricing Plans'!D5 -> 9999 | J21: ='Pricing Plans'!D5 -> 9999 | K21: ='Pricing Plans'!D5 -> 9999 | L21: IDR/mo
B22: Pro price (IDR/mo) | C22: ='Pricing Plans'!E5 -> 24999 | D22: ='Pricing Plans'!E5 -> 24999 | E22: ='Pricing Plans'!E5 -> 24999 | F22: ='Pricing Plans'!E5 -> 24999 | G22: ='Pricing Plans'!E5 -> 24999 | H22: ='Pricing Plans'!E5 -> 24999 | I22: ='Pricing Plans'!E5 -> 24999 | J22: ='Pricing Plans'!E5 -> 24999 | K22: ='Pricing Plans'!E5 -> 24999 | L22: IDR/mo
B23: Business price (IDR/mo) | C23: ='Pricing Plans'!F5 -> 34999 | D23: ='Pricing Plans'!F5 -> 34999 | E23: ='Pricing Plans'!F5 -> 34999 | F23: ='Pricing Plans'!F5 -> 34999 | G23: ='Pricing Plans'!F5 -> 34999 | H23: ='Pricing Plans'!F5 -> 34999 | I23: ='Pricing Plans'!F5 -> 34999 | J23: ='Pricing Plans'!F5 -> 34999 | K23: ='Pricing Plans'!F5 -> 34999 | L23: IDR/mo
B25: D. MONTHLY RECURRING REVENUE (MRR)
B26: MRR — Starter (IDR) | C26: =C14*C21 -> 29997 | D26: =D14*D21 -> 129987 | E26: =E14*E21 -> 249975 | F26: =F14*F21 -> 499950 | G26: =G14*G21 -> 1249875 | H26: =H14*H21 -> 2499750 | I26: =I14*I21 -> 4999500 | J26: =J14*J21 -> 12498750 | K26: =K14*K21 -> 24997500 | L26: IDR/mo
B27: MRR — Pro (IDR) | C27: =C15*C22 -> 24999 | D27: =D15*D22 -> 149994 | E27: =E15*E22 -> 299988 | F27: =F15*F22 -> 599976 | G27: =G15*G22 -> 1499940 | H27: =H15*H22 -> 2999880 | I27: =I15*I22 -> 5999760 | J27: =J15*J22 -> 14999400 | K27: =K15*K22 -> 29998800 | L27: IDR/mo
B28: MRR — Business (IDR) | C28: =C16*C23 -> 0 | D28: =D16*D23 -> 69998 | E28: =E16*E23 -> 104997 | F28: =F16*F23 -> 209994 | G28: =G16*G23 -> 524985 | H28: =H16*H23 -> 1049970 | I28: =I16*I23 -> 2099940 | J28: =J16*J23 -> 5249850 | K28: =K16*K23 -> 10499700 | L28: IDR/mo
B29: TOTAL MRR (IDR/mo) | C29: =C26+C27+C28 -> 54996 | D29: =D26+D27+D28 -> 349979 | E29: =E26+E27+E28 -> 654960 | F29: =F26+F27+F28 -> 1309920 | G29: =G26+G27+G28 -> 3274800 | H29: =H26+H27+H28 -> 6549600 | I29: =I26+I27+I28 -> 13099200 | J29: =J26+J27+J28 -> 32748000 | K29: =K26+K27+K28 -> 65496000 | L29: IDR/mo
B30: ARR (IDR/yr) | C30: =C29*12 -> 659952 | D30: =D29*12 -> 4199748 | E30: =E29*12 -> 7859520 | F30: =F29*12 -> 15719040 | G30: =G29*12 -> 39297600 | H30: =H29*12 -> 78595200 | I30: =I29*12 -> 157190400 | J30: =J29*12 -> 392976000 | K30: =K29*12 -> 785952000 | L30: IDR/yr
B32: E. REVENUE IN USD EQUIVALENT
B33: TOTAL MRR (USD/mo) | C33: =C29/Assumptions!C47 -> 3.1697983 | D33: =D29/Assumptions!C47 -> 20.1717 | E33: =E29/Assumptions!C47 -> 37.749856 | F33: =F29/Assumptions!C47 -> 75.499712 | G33: =G29/Assumptions!C47 -> 188.74928 | H33: =H29/Assumptions!C47 -> 377.49856 | I33: =I29/Assumptions!C47 -> 754.99712 | J33: =J29/Assumptions!C47 -> 1887.4928 | K33: =K29/Assumptions!C47 -> 3774.9856 | L33: USD/mo
B34: ARR (USD/yr) | C34: =C30/Assumptions!C47 -> 38.037579 | D34: =D30/Assumptions!C47 -> 242.0604 | E34: =E30/Assumptions!C47 -> 452.99827 | F34: =F30/Assumptions!C47 -> 905.99654 | G34: =G30/Assumptions!C47 -> 2264.9914 | H34: =H30/Assumptions!C47 -> 4529.9827 | I34: =I30/Assumptions!C47 -> 9059.9654 | J34: =J30/Assumptions!C47 -> 22649.914 | K34: =K30/Assumptions!C47 -> 45299.827 | L34: USD/yr
B36: F. UNIT ECONOMICS
B37: ARPU — all users (IDR/mo) | C37: =IF(10>0,C29/10,0) -> 5499.6 | D37: =IF(50>0,D29/50,0) -> 6999.58 | E37: =IF(100>0,E29/100,0) -> 6549.6 | F37: =IF(200>0,F29/200,0) -> 6549.6 | G37: =IF(500>0,G29/500,0) -> 6549.6 | H37: =IF(1000>0,H29/1000,0) -> 6549.6 | I37: =IF(2000>0,I29/2000,0) -> 6549.6 | J37: =IF(5000>0,J29/5000,0) -> 6549.6 | K37: =IF(10000>0,K29/10000,0) -> 6549.6 | L37: IDR/user
B38: ARPU — paid users only (IDR/mo) | C38: =IF(C17>0,C29/C17,0) -> 13749 | D38: =IF(D17>0,D29/D17,0) -> 16665.667 | E38: =IF(E17>0,E29/E17,0) -> 16374 | F38: =IF(F17>0,F29/F17,0) -> 16374 | G38: =IF(G17>0,G29/G17,0) -> 16374 | H38: =IF(H17>0,H29/H17,0) -> 16374 | I38: =IF(I17>0,I29/I17,0) -> 16374 | J38: =IF(J17>0,J29/J17,0) -> 16374 | K38: =IF(K17>0,K29/K17,0) -> 16374 | L38: IDR/paid user

Sheet P&L Summary
B1: P&L SUMMARY — Revenue vs Cost vs Profit
B2: All in IDR. Green = profit. Orange = loss. Cross-linked from Revenue, AI Cost, Infra Cost.
B4: Line Item | C4: 10 users | D4: 50 users | E4: 100 users | F4: 200 users | G4: 500 users | H4: 1,000 users | I4: 2,000 users | J4: 5,000 users | K4: 10,000 users | L4: Unit
B5: REVENUE
B6: Total MRR (IDR/mo) | C6: ='Revenue Model'!C29 -> 54996 | D6: ='Revenue Model'!D29 -> 349979 | E6: ='Revenue Model'!E29 -> 654960 | F6: ='Revenue Model'!F29 -> 1309920 | G6: ='Revenue Model'!G29 -> 3274800 | H6: ='Revenue Model'!H29 -> 6549600 | I6: ='Revenue Model'!I29 -> 13099200 | J6: ='Revenue Model'!J29 -> 32748000 | K6: ='Revenue Model'!K29 -> 65496000 | L6: IDR/mo
B8: COSTS
B9: AI Cost — Claude Haiku (IDR/mo) | C9: ='AI Cost'!C29 -> 737527.68 | D9: ='AI Cost'!D29 -> 3687638.4 | E9: ='AI Cost'!E29 -> 7375276.8 | F9: ='AI Cost'!F29 -> 14750554 | G9: ='AI Cost'!G29 -> 36876384 | H9: ='AI Cost'!H29 -> 73752768 | I9: ='AI Cost'!I29 -> 147505536 | J9: ='AI Cost'!J29 -> 368763840 | K9: ='AI Cost'!K29 -> 737527680 | L9: IDR/mo
B10: Infrastructure (IDR/mo) | C10: ='Infra Cost'!C17 -> 433750 | D10: ='Infra Cost'!D17 -> 433750 | E10: ='Infra Cost'!E17 -> 867500 | F10: ='Infra Cost'!F17 -> 954250 | G10: ='Infra Cost'!G17 -> 1301250 | H10: ='Infra Cost'!H17 -> 11260150 | I10: ='Infra Cost'!I17 -> 11260150 | J10: ='Infra Cost'!J17 -> 11260150 | K10: ='Infra Cost'!K17 -> 11260150 | L10: IDR/mo
B11: TOTAL COST (IDR/mo) | C11: =C9+C10 -> 1171277.7 | D11: =D9+D10 -> 4121388.4 | E11: =E9+E10 -> 8242776.8 | F11: =F9+F10 -> 15704804 | G11: =G9+G10 -> 38177634 | H11: =H9+H10 -> 85012918 | I11: =I9+I10 -> 158765686 | J11: =J9+J10 -> 380023990 | K11: =K9+K10 -> 748787830 | L11: IDR/mo
B13: PROFIT / LOSS
B14: GROSS PROFIT (IDR/mo) | C14: =C6-C11 -> -1116281.7 | D14: =D6-D11 -> -3771409.4 | E14: =E6-E11 -> -7587816.8 | F14: =F6-F11 -> -14394884 | G14: =G6-G11 -> -34902834 | H14: =H6-H11 -> -78463318 | I14: =I6-I11 -> -145666486 | J14: =J6-J11 -> -347275990 | K14: =K6-K11 -> -683291830 | L14: IDR/mo
B15: Gross Margin % | C15: =IF(C6<>0,(C6-C11)/C6,0) -> -20.297507 | D15: =IF(D6<>0,(D6-D11)/D6,0) -> -10.776102 | E15: =IF(E6<>0,(E6-E11)/E6,0) -> -11.585161 | F15: =IF(F6<>0,(F6-F11)/F6,0) -> -10.989132 | G15: =IF(G6<>0,(G6-G11)/G6,0) -> -10.658005 | H15: =IF(H6<>0,(H6-H11)/H6,0) -> -11.979864 | I15: =IF(I6<>0,(I6-I11)/I6,0) -> -11.120258 | J15: =IF(J6<>0,(J6-J11)/J6,0) -> -10.604495 | K15: =IF(K6<>0,(K6-K11)/K6,0) -> -10.432573 | L15: %
B16: Cost per User (IDR/mo) | C16: =C11/10 -> 117127.77 | D16: =D11/50 -> 82427.768 | E16: =E11/100 -> 82427.768 | F16: =F11/200 -> 78524.018 | G16: =G11/500 -> 76355.268 | H16: =H11/1000 -> 85012.918 | I16: =I11/2000 -> 79382.843 | J16: =J11/5000 -> 76004.798 | K16: =K11/10000 -> 74878.783 | L16: IDR/user
B17: Revenue per User (IDR/mo) | C17: =C6/10 -> 5499.6 | D17: =D6/50 -> 6999.58 | E17: =E6/100 -> 6549.6 | F17: =F6/200 -> 6549.6 | G17: =G6/500 -> 6549.6 | H17: =H6/1000 -> 6549.6 | I17: =I6/2000 -> 6549.6 | J17: =J6/5000 -> 6549.6 | K17: =K6/10000 -> 6549.6 | L17: IDR/user
B18: Profit per User (IDR/mo) | C18: =C17-C16 -> -111628.17 | D18: =D17-D16 -> -75428.188 | E18: =E17-E16 -> -75878.168 | F18: =F17-F16 -> -71974.418 | G18: =G17-G16 -> -69805.668 | H18: =H17-H16 -> -78463.318 | I18: =I17-I16 -> -72833.243 | J18: =J17-J16 -> -69455.198 | K18: =K17-K16 -> -68329.183 | L18: IDR/user
B20: USD EQUIVALENT
B21: Revenue (USD/mo) | C21: ='Revenue Model'!C33 -> 3.1697983 | D21: ='Revenue Model'!D33 -> 20.1717 | E21: ='Revenue Model'!E33 -> 37.749856 | F21: ='Revenue Model'!F33 -> 75.499712 | G21: ='Revenue Model'!G33 -> 188.74928 | H21: ='Revenue Model'!H33 -> 377.49856 | I21: ='Revenue Model'!I33 -> 754.99712 | J21: ='Revenue Model'!J33 -> 1887.4928 | K21: ='Revenue Model'!K33 -> 3774.9856 | L21: USD/mo
B22: Total Cost (USD/mo) | C22: =(C9+C10)/Assumptions!C47 -> 67.5088 | D22: =(D9+D10)/Assumptions!C47 -> 237.544 | E22: =(E9+E10)/Assumptions!C47 -> 475.088 | F22: =(F9+F10)/Assumptions!C47 -> 905.176 | G22: =(G9+G10)/Assumptions!C47 -> 2200.44 | H22: =(H9+H10)/Assumptions!C47 -> 4899.88 | I22: =(I9+I10)/Assumptions!C47 -> 9150.76 | J22: =(J9+J10)/Assumptions!C47 -> 21903.4 | K22: =(K9+K10)/Assumptions!C47 -> 43157.8 | L22: USD/mo
B23: Gross Profit (USD/mo) | C23: =C14/Assumptions!C47 -> -64.339002 | D23: =D14/Assumptions!C47 -> -217.3723 | E23: =E14/Assumptions!C47 -> -437.33814 | F23: =F14/Assumptions!C47 -> -829.67629 | G23: =G14/Assumptions!C47 -> -2011.6907 | H23: =H14/Assumptions!C47 -> -4522.3814 | I23: =I14/Assumptions!C47 -> -8395.7629 | J23: =J14/Assumptions!C47 -> -20015.907 | K23: =K14/Assumptions!C47 -> -39382.814 | L23: USD/mo
B26: BREAKEVEN ANALYSIS
B27: Breakeven status | C27: =IF(C14>=0,"✓ Profitable","✗ Loss") -> ✗ Loss | D27: =IF(D14>=0,"✓ Profitable","✗ Loss") -> ✗ Loss | E27: =IF(E14>=0,"✓ Profitable","✗ Loss") -> ✗ Loss | F27: =IF(F14>=0,"✓ Profitable","✗ Loss") -> ✗ Loss | G27: =IF(G14>=0,"✓ Profitable","✗ Loss") -> ✗ Loss | H27: =IF(H14>=0,"✓ Profitable","✗ Loss") -> ✗ Loss | I27: =IF(I14>=0,"✓ Profitable","✗ Loss") -> ✗ Loss | J27: =IF(J14>=0,"✓ Profitable","✗ Loss") -> ✗ Loss | K27: =IF(K14>=0,"✓ Profitable","✗ Loss") -> ✗ Loss
B28: Min paid users to break even | C28: =IFERROR(ROUNDUP(C11/'Pricing Plans'!D5,0),"-") -> 118 | D28: =IFERROR(ROUNDUP(D11/'Pricing Plans'!D5,0),"-") -> 413 | E28: =IFERROR(ROUNDUP(E11/'Pricing Plans'!D5,0),"-") -> 825 | F28: =IFERROR(ROUNDUP(F11/'Pricing Plans'!D5,0),"-") -> 1571 | G28: =IFERROR(ROUNDUP(G11/'Pricing Plans'!D5,0),"-") -> 3819 | H28: =IFERROR(ROUNDUP(H11/'Pricing Plans'!D5,0),"-") -> 8503 | I28: =IFERROR(ROUNDUP(I11/'Pricing Plans'!D5,0),"-") -> 15879 | J28: =IFERROR(ROUNDUP(J11/'Pricing Plans'!D5,0),"-") -> 38007 | K28: =IFERROR(ROUNDUP(K11/'Pricing Plans'!D5,0),"-") -> 74887 | L28: Starter-equiv users needed
B31: KEY INSIGHTS
B32: • At 100 users (base mix 60/25/12/3%): MRR ≈ Rp 600,000 — covers infra but not enough margin yet.
B33: • At 500 users: MRR ≈ Rp 3,000,000. Vercel Pro kicks in. AI cost still negligible (<1% of cost).
B34: • Supabase Team ($599/mo = Rp 9.6M) hits at 1,000 users — revenue must be >Rp 10M to sustain.
B35: • At 2,000 users: First meaningful profitability if plan mix holds and churn is controlled.
B36: • AI cost never exceeds 5% of total cost at any scale — infra (esp. Supabase) dominates.
B37: • NLP mode adds ~Rp 200-2,000/mo at 100-1,000 users — negligible. Worth the UX improvement.
B38: • Suggested min pricing: Starter Rp 9,000 / Pro Rp 29,000 / Business Rp 79,000 per month.

Sheet Scenario
B1: SCENARIO MODEL — Conservative / Base / Growth
B2: Multiplier applied to user activity. Change multipliers in row 6 (blue). Plan mix unchanged.
C4: Conservative | G4: Base Case | K4: Growth
C5: 100 users | D5: 500 users | E5: 1,000 users | G5: 100 users | H5: 500 users | I5: 1,000 users | K5: 100 users | L5: 500 users | M5: 1,000 users
B6: Activity multiplier (vs base assumptions) | C6: 0.6 | D6: 0.6 | E6: 0.6 | G6: 1 | H6: 1 | I6: 1 | K6: 1.5 | L6: 1.5 | M6: 1.5
B7: AI Cost (IDR/mo) | C7: =((ROUND(100*C6*Assumptions!C5*Assumptions!C6*Assumptions!C8*Assumptions!C21,0)+ROUND(100*C6*Assumptions!C5*Assumptions!C7*Assumptions!C8*Assumptions!C23,0)+ROUND(100*C6*Assumptions!C11*Assumptions!C12*Assumptions!C13*Assumptions!C25,0))/1000000*Assumptions!C17+(ROUND(100*C6*Assumptions!C5*Assumptions!C6*Assumptions!C8*Assumptions!C22,0)+ROUND(100*C6*Assumptions!C5*Assumptions!C7*Assumptions!C8*Assumptions!C24,0)+ROUND(100*C6*Assumptions!C11*Assumptions!C12*Assumptions!C13*Assumptions!C26,0))/1000000*Assumptions!C18)*Assumptions!C47 -> 4425166.1 | D7: =((ROUND(500*D6*Assumptions!C5*Assumptions!C6*Assumptions!C8*Assumptions!C21,0)+ROUND(500*D6*Assumptions!C5*Assumptions!C7*Assumptions!C8*Assumptions!C23,0)+ROUND(500*D6*Assumptions!C11*Assumptions!C12*Assumptions!C13*Assumptions!C25,0))/1000000*Assumptions!C17+(ROUND(500*D6*Assumptions!C5*Assumptions!C6*Assumptions!C8*Assumptions!C22,0)+ROUND(500*D6*Assumptions!C5*Assumptions!C7*Assumptions!C8*Assumptions!C24,0)+ROUND(500*D6*Assumptions!C11*Assumptions!C12*Assumptions!C13*Assumptions!C26,0))/1000000*Assumptions!C18)*Assumptions!C47 -> 22125830 | E7: =((ROUND(1000*E6*Assumptions!C5*Assumptions!C6*Assumptions!C8*Assumptions!C21,0)+ROUND(1000*E6*Assumptions!C5*Assumptions!C7*Assumptions!C8*Assumptions!C23,0)+ROUND(1000*E6*Assumptions!C11*Assumptions!C12*Assumptions!C13*Assumptions!C25,0))/1000000*Assumptions!C17+(ROUND(1000*E6*Assumptions!C5*Assumptions!C6*Assumptions!C8*Assumptions!C22,0)+ROUND(1000*E6*Assumptions!C5*Assumptions!C7*Assumptions!C8*Assumptions!C24,0)+ROUND(1000*E6*Assumptions!C11*Assumptions!C12*Assumptions!C13*Assumptions!C26,0))/1000000*Assumptions!C18)*Assumptions!C47 -> 44251661 | G7: =((ROUND(100*G6*Assumptions!C5*Assumptions!C6*Assumptions!C8*Assumptions!C21,0)+ROUND(100*G6*Assumptions!C5*Assumptions!C7*Assumptions!C8*Assumptions!C23,0)+ROUND(100*G6*Assumptions!C11*Assumptions!C12*Assumptions!C13*Assumptions!C25,0))/1000000*Assumptions!C17+(ROUND(100*G6*Assumptions!C5*Assumptions!C6*Assumptions!C8*Assumptions!C22,0)+ROUND(100*G6*Assumptions!C5*Assumptions!C7*Assumptions!C8*Assumptions!C24,0)+ROUND(100*G6*Assumptions!C11*Assumptions!C12*Assumptions!C13*Assumptions!C26,0))/1000000*Assumptions!C18)*Assumptions!C47 -> 7375276.8 | H7: =((ROUND(500*H6*Assumptions!C5*Assumptions!C6*Assumptions!C8*Assumptions!C21,0)+ROUND(500*H6*Assumptions!C5*Assumptions!C7*Assumptions!C8*Assumptions!C23,0)+ROUND(500*H6*Assumptions!C11*Assumptions!C12*Assumptions!C13*Assumptions!C25,0))/1000000*Assumptions!C17+(ROUND(500*H6*Assumptions!C5*Assumptions!C6*Assumptions!C8*Assumptions!C22,0)+ROUND(500*H6*Assumptions!C5*Assumptions!C7*Assumptions!C8*Assumptions!C24,0)+ROUND(500*H6*Assumptions!C11*Assumptions!C12*Assumptions!C13*Assumptions!C26,0))/1000000*Assumptions!C18)*Assumptions!C47 -> 36876384 | I7: =((ROUND(1000*I6*Assumptions!C5*Assumptions!C6*Assumptions!C8*Assumptions!C21,0)+ROUND(1000*I6*Assumptions!C5*Assumptions!C7*Assumptions!C8*Assumptions!C23,0)+ROUND(1000*I6*Assumptions!C11*Assumptions!C12*Assumptions!C13*Assumptions!C25,0))/1000000*Assumptions!C17+(ROUND(1000*I6*Assumptions!C5*Assumptions!C6*Assumptions!C8*Assumptions!C22,0)+ROUND(1000*I6*Assumptions!C5*Assumptions!C7*Assumptions!C8*Assumptions!C24,0)+ROUND(1000*I6*Assumptions!C11*Assumptions!C12*Assumptions!C13*Assumptions!C26,0))/1000000*Assumptions!C18)*Assumptions!C47 -> 73752768 | K7: =((ROUND(100*K6*Assumptions!C5*Assumptions!C6*Assumptions!C8*Assumptions!C21,0)+ROUND(100*K6*Assumptions!C5*Assumptions!C7*Assumptions!C8*Assumptions!C23,0)+ROUND(100*K6*Assumptions!C11*Assumptions!C12*Assumptions!C13*Assumptions!C25,0))/1000000*Assumptions!C17+(ROUND(100*K6*Assumptions!C5*Assumptions!C6*Assumptions!C8*Assumptions!C22,0)+ROUND(100*K6*Assumptions!C5*Assumptions!C7*Assumptions!C8*Assumptions!C24,0)+ROUND(100*K6*Assumptions!C11*Assumptions!C12*Assumptions!C13*Assumptions!C26,0))/1000000*Assumptions!C18)*Assumptions!C47 -> 11062915 | L7: =((ROUND(500*L6*Assumptions!C5*Assumptions!C6*Assumptions!C8*Assumptions!C21,0)+ROUND(500*L6*Assumptions!C5*Assumptions!C7*Assumptions!C8*Assumptions!C23,0)+ROUND(500*L6*Assumptions!C11*Assumptions!C12*Assumptions!C13*Assumptions!C25,0))/1000000*Assumptions!C17+(ROUND(500*L6*Assumptions!C5*Assumptions!C6*Assumptions!C8*Assumptions!C22,0)+ROUND(500*L6*Assumptions!C5*Assumptions!C7*Assumptions!C8*Assumptions!C24,0)+ROUND(500*L6*Assumptions!C11*Assumptions!C12*Assumptions!C13*Assumptions!C26,0))/1000000*Assumptions!C18)*Assumptions!C47 -> 55314576 | M7: =((ROUND(1000*M6*Assumptions!C5*Assumptions!C6*Assumptions!C8*Assumptions!C21,0)+ROUND(1000*M6*Assumptions!C5*Assumptions!C7*Assumptions!C8*Assumptions!C23,0)+ROUND(1000*M6*Assumptions!C11*Assumptions!C12*Assumptions!C13*Assumptions!C25,0))/1000000*Assumptions!C17+(ROUND(1000*M6*Assumptions!C5*Assumptions!C6*Assumptions!C8*Assumptions!C22,0)+ROUND(1000*M6*Assumptions!C5*Assumptions!C7*Assumptions!C8*Assumptions!C24,0)+ROUND(1000*M6*Assumptions!C11*Assumptions!C12*Assumptions!C13*Assumptions!C26,0))/1000000*Assumptions!C18)*Assumptions!C47 -> 110629152
B8: Infrastructure (IDR/mo) | C8: =((IF(100>=Assumptions!C41,Assumptions!C42,Assumptions!C31))+(IF(100>=Assumptions!C43,Assumptions!C44,IF(100>=Assumptions!C37,Assumptions!C38,Assumptions!C32)))+(IF(100>=Assumptions!C39,Assumptions!C40,Assumptions!C33))+Assumptions!C34)*Assumptions!C47 -> 867500 | D8: =((IF(500>=Assumptions!C41,Assumptions!C42,Assumptions!C31))+(IF(500>=Assumptions!C43,Assumptions!C44,IF(500>=Assumptions!C37,Assumptions!C38,Assumptions!C32)))+(IF(500>=Assumptions!C39,Assumptions!C40,Assumptions!C33))+Assumptions!C34)*Assumptions!C47 -> 1301250 | E8: =((IF(1000>=Assumptions!C41,Assumptions!C42,Assumptions!C31))+(IF(1000>=Assumptions!C43,Assumptions!C44,IF(1000>=Assumptions!C37,Assumptions!C38,Assumptions!C32)))+(IF(1000>=Assumptions!C39,Assumptions!C40,Assumptions!C33))+Assumptions!C34)*Assumptions!C47 -> 11260150 | G8: =((IF(100>=Assumptions!C41,Assumptions!C42,Assumptions!C31))+(IF(100>=Assumptions!C43,Assumptions!C44,IF(100>=Assumptions!C37,Assumptions!C38,Assumptions!C32)))+(IF(100>=Assumptions!C39,Assumptions!C40,Assumptions!C33))+Assumptions!C34)*Assumptions!C47 -> 867500 | H8: =((IF(500>=Assumptions!C41,Assumptions!C42,Assumptions!C31))+(IF(500>=Assumptions!C43,Assumptions!C44,IF(500>=Assumptions!C37,Assumptions!C38,Assumptions!C32)))+(IF(500>=Assumptions!C39,Assumptions!C40,Assumptions!C33))+Assumptions!C34)*Assumptions!C47 -> 1301250 | I8: =((IF(1000>=Assumptions!C41,Assumptions!C42,Assumptions!C31))+(IF(1000>=Assumptions!C43,Assumptions!C44,IF(1000>=Assumptions!C37,Assumptions!C38,Assumptions!C32)))+(IF(1000>=Assumptions!C39,Assumptions!C40,Assumptions!C33))+Assumptions!C34)*Assumptions!C47 -> 11260150 | K8: =((IF(100>=Assumptions!C41,Assumptions!C42,Assumptions!C31))+(IF(100>=Assumptions!C43,Assumptions!C44,IF(100>=Assumptions!C37,Assumptions!C38,Assumptions!C32)))+(IF(100>=Assumptions!C39,Assumptions!C40,Assumptions!C33))+Assumptions!C34)*Assumptions!C47 -> 867500 | L8: =((IF(500>=Assumptions!C41,Assumptions!C42,Assumptions!C31))+(IF(500>=Assumptions!C43,Assumptions!C44,IF(500>=Assumptions!C37,Assumptions!C38,Assumptions!C32)))+(IF(500>=Assumptions!C39,Assumptions!C40,Assumptions!C33))+Assumptions!C34)*Assumptions!C47 -> 1301250 | M8: =((IF(1000>=Assumptions!C41,Assumptions!C42,Assumptions!C31))+(IF(1000>=Assumptions!C43,Assumptions!C44,IF(1000>=Assumptions!C37,Assumptions!C38,Assumptions!C32)))+(IF(1000>=Assumptions!C39,Assumptions!C40,Assumptions!C33))+Assumptions!C34)*Assumptions!C47 -> 11260150
B9: TOTAL COST (IDR/mo) | C9: =C7+C8 -> 5292666.1 | D9: =D7+D8 -> 23427080 | E9: =E7+E8 -> 55511811 | G9: =G7+G8 -> 8242776.8 | H9: =H7+H8 -> 38177634 | I9: =I7+I8 -> 85012918 | K9: =K7+K8 -> 11930415 | L9: =L7+L8 -> 56615826 | M9: =M7+M8 -> 121889302
B10: Revenue MRR (IDR/mo) | C10: =(ROUND(100*C7,0)*'Pricing Plans'!D5)+(ROUND(100*C8,0)*'Pricing Plans'!E5)+(ROUND(100*C9,0)*'Pricing Plans'!F5) -> 25117188826784 | D10: =(ROUND(500*D7,0)*'Pricing Plans'!D5)+(ROUND(500*D8,0)*'Pricing Plans'!E5)+(ROUND(500*D9,0)*'Pricing Plans'!F5) -> 536845256919600 | E10: =(ROUND(1000*E7,0)*'Pricing Plans'!D5)+(ROUND(1000*E8,0)*'Pricing Plans'!E5)+(ROUND(1000*E9,0)*'Pricing Plans'!F5) -> 2.6668227e+15 | G10: =(ROUND(100*G7,0)*'Pricing Plans'!D5)+(ROUND(100*G8,0)*'Pricing Plans'!E5)+(ROUND(100*G9,0)*'Pricing Plans'!F5) -> 38392097044640 | H10: =(ROUND(500*H7,0)*'Pricing Plans'!D5)+(ROUND(500*H8,0)*'Pricing Plans'!E5)+(ROUND(500*H9,0)*'Pricing Plans'!F5) -> 868717962366000 | I10: =(ROUND(1000*I7,0)*'Pricing Plans'!D5)+(ROUND(1000*I8,0)*'Pricing Plans'!E5)+(ROUND(1000*I9,0)*'Pricing Plans'!F5) -> 3.9943135e+15 | K10: =(ROUND(100*K7,0)*'Pricing Plans'!D5)+(ROUND(100*K8,0)*'Pricing Plans'!E5)+(ROUND(100*K9,0)*'Pricing Plans'!F5) -> 54985732316960 | L10: =(ROUND(500*L7,0)*'Pricing Plans'!D5)+(ROUND(500*L8,0)*'Pricing Plans'!E5)+(ROUND(500*L9,0)*'Pricing Plans'!F5) -> 1.2835588e+15 | M10: =(ROUND(1000*M7,0)*'Pricing Plans'!D5)+(ROUND(1000*M8,0)*'Pricing Plans'!E5)+(ROUND(1000*M9,0)*'Pricing Plans'!F5) -> 5.6536771e+15
B11: GROSS PROFIT (IDR/mo) | C11: =C10-C9 -> 2.5117184e+13 | D11: =D10-D9 -> 5.3684523e+14 | E11: =E10-E9 -> 2.6668227e+15 | G11: =G10-G9 -> 3.8392089e+13 | H11: =H10-H9 -> 868717924188366 | I11: =I10-I9 -> 3.9943134e+15 | K11: =K10-K9 -> 5.498572e+13 | L11: =L10-L9 -> 1.2835588e+15 | M11: =M10-M9 -> 5.6536769e+15
B12: Gross Margin % | C12: =IF(C10<>0,C11/C10,0) -> 0.99999979 | D12: =IF(D10<>0,D11/D10,0) -> 0.99999996 | E12: =IF(E10<>0,E11/E10,0) -> 0.99999998 | G12: =IF(G10<>0,G11/G10,0) -> 0.99999979 | H12: =IF(H10<>0,H11/H10,0) -> 0.99999996 | I12: =IF(I10<>0,I11/I10,0) -> 0.99999998 | K12: =IF(K10<>0,K11/K10,0) -> 0.99999978 | L12: =IF(L10<>0,L11/L10,0) -> 0.99999996 | M12: =IF(M10<>0,M11/M10,0) -> 0.99999998
B13: Cost per User (IDR/mo) | C13: =C9/100 -> 52926.661 | D13: =D9/500 -> 46854.161 | E13: =E9/1000 -> 55511.811 | G13: =G9/100 -> 82427.768 | H13: =H9/500 -> 76355.268 | I13: =I9/1000 -> 85012.918 | K13: =K9/100 -> 119304.15 | L13: =L9/500 -> 113231.65 | M13: =M9/1000 -> 121889.3
B14: Revenue per User (IDR/mo) | C14: =C10/100 -> 2.5117189e+11 | D14: =D10/500 -> 1.0736905e+12 | E14: =E10/1000 -> 2.6668227e+12 | G14: =G10/100 -> 3.8392097e+11 | H14: =H10/500 -> 1737435924732 | I14: =I10/1000 -> 3994313534164 | K14: =K10/100 -> 5.4985732e+11 | L14: =L10/500 -> 2567117688348 | M14: =M10/1000 -> 5653677061396
B15: Status | C15: =IF(C11>=0,"✓ Profit","✗ Loss") -> ✓ Profit | D15: =IF(D11>=0,"✓ Profit","✗ Loss") -> ✓ Profit | E15: =IF(E11>=0,"✓ Profit","✗ Loss") -> ✓ Profit | G15: =IF(G11>=0,"✓ Profit","✗ Loss") -> ✓ Profit | H15: =IF(H11>=0,"✓ Profit","✗ Loss") -> ✓ Profit | I15: =IF(I11>=0,"✓ Profit","✗ Loss") -> ✓ Profit | K15: =IF(K11>=0,"✓ Profit","✗ Loss") -> ✓ Profit | L15: =IF(L11>=0,"✓ Profit","✗ Loss") -> ✓ Profit | M15: =IF(M11>=0,"✓ Profit","✗ Loss") -> ✓ Profit
